<?xml version="1.0" ?>
<!-- 26.5654866776462 -->
<!-- This URDF was automatically created by SolidWorks to URDF Exporter! Originally created by Stephen Brawner (brawner@gmail.com) 
     Commit Version: 1.6.0-4-g7f85cfe  Build Version: 1.6.7995.38578
     For more information, please see http://wiki.ros.org/sw_urdf_exporter -->
<robot
  name="car" xmlns:xacro="http://ros.org/wiki/xacro">
  <link name="dummy_link"></link>
  <link
    name="base_link">
    <inertial>
      <origin
        xyz="0.410739320383848 -0.760919245062769 0.503217025483666"
        rpy="0 0 0" />
      <mass
        value="26.5654866776462" />
      <inertia
        ixx="0.311711032402344"
        ixy="6.4374503991327E-17"
        ixz="-1.18915697835174E-17"
        iyy="2.95081279665845"
        iyz="-2.01443248286315E-18"
        izz="3.21497060567305" />
    </inertial>
    <visual>
      <origin
        xyz="0 0 0"
        rpy="0 0 0" />
      <geometry>
        <mesh
          filename="package://car/meshes/base_link.STL" />
      </geometry>
      <material
        name="">
        <color
          rgba="0.792156862745098 0.819607843137255 0.933333333333333 1" />
      </material>
    </visual>
    <collision>
      <origin
        xyz="0 0 0"
        rpy="0 0 0" />
      <geometry>
        <mesh
          filename="package://car/meshes/base_link.STL" />
      </geometry>
    </collision>
  </link>
    <joint name="dummy_joint" type="fixed">
    <origin rpy="0 0 0" xyz="0 0 0" />
    <parent link="dummy_link"/>
    <child link="base_link"/>
  </joint>
  <link
    name="front_left_axle_link">
    <inertial>
      <origin
        xyz="0.0605635681645035 0.0250000379534826 1.01927197793117E-08"
        rpy="0 0 0" />
      <mass
        value="0.225126111623142" />
      <inertia
        ixx="6.99511377566151E-05"
        ixy="-1.9388751550408E-10"
        ixz="-2.5215377280019E-10"
        iyy="0.000642301895072359"
        iyz="-2.1138743748584E-10"
        izz="0.000632842018939609" />
    </inertial>
    <visual>
      <origin
        xyz="0 0 0"
        rpy="0 0 0" />
      <geometry>
        <mesh
          filename="package://car/meshes/front_left_axle_link.STL" />
      </geometry>
      <material
        name="">
        <color
          rgba="0.792156862745098 0.819607843137255 0.933333333333333 1" />
      </material>
    </visual>
    <collision>
      <origin
        xyz="0 0 0"
        rpy="0 0 0" />
      <geometry>
        <mesh
          filename="package://car/meshes/front_left_axle_link.STL" />
      </geometry>
    </collision>
  </link>
  <joint
    name="front_left_axle_joint"
    type="revolute">
    <origin
      xyz="0.860739320383848 -0.510919245062769 0.47756660413794"
      rpy="1.5707963267949 0 1.5707963267949" />
    <parent
      link="base_link" />
    <child
      link="front_left_axle_link" />
    <axis
      xyz="0 1 0" />
    <limit
      lower="-0.61"
      upper="0.61"
      effort="100"
      velocity="100" />
  </joint>
  <link
    name="front_left_wheel_link">
    <inertial>
      <origin
        xyz="4.44089209850063E-16 -2.4980018054066E-16 -0.025"
        rpy="0 0 0" />
      <mass
        value="6.21012679962811" />
      <inertia
        ixx="0.0721461700805678"
        ixy="5.20417042793042E-18"
        ixz="4.71601633982946E-19"
        iyy="0.0721461700805678"
        iyz="7.87347296425907E-21"
        izz="0.141888005291817" />
    </inertial>
    <visual>
      <origin
        xyz="0 0 0"
        rpy="0 0 0" />
      <geometry>
        <mesh
          filename="package://car/meshes/front_left_wheel_link.STL" />
      </geometry>
      <material
        name="">
        <color
          rgba="0.792156862745098 0.819607843137255 0.933333333333333 1" />
      </material>
    </visual>
    <collision>
      <origin
        xyz="0 0 0"
        rpy="0 0 0" />
      <geometry>
        <mesh
          filename="package://car/meshes/front_left_wheel_link.STL" />
      </geometry>
    </collision>
  </link>
  <joint
    name="front_left_wheel_joint"
    type="continuous">
    <origin
      xyz="0.0999999999999999 0.0249999999999999 0"
      rpy="-1.5707963267949 -1.28850619485261 1.5707963267949" />
    <parent
      link="front_left_axle_link" />
    <child
      link="front_left_wheel_link" />
    <axis
      xyz="0 0 1" />
    <limit
      effort="100"
      velocity="100" />
  </joint>
  <link
    name="front_right_axle_link">
    <inertial>
      <origin
        xyz="0.0605635681645036 0.0249999620465176 -1.01927197793117E-08"
        rpy="0 0 0" />
      <mass
        value="0.225126111623142" />
      <inertia
        ixx="6.99511377566151E-05"
        ixy="1.93887515879403E-10"
        ixz="2.52153773107898E-10"
        iyy="0.000642301895072357"
        iyz="-2.11387437456505E-10"
        izz="0.000632842018939609" />
    </inertial>
    <visual>
      <origin
        xyz="0 0 0"
        rpy="0 0 0" />
      <geometry>
        <mesh
          filename="package://car/meshes/front_right_axle_link.STL" />
      </geometry>
      <material
        name="">
        <color
          rgba="0.792156862745098 0.819607843137255 0.933333333333333 1" />
      </material>
    </visual>
    <collision>
      <origin
        xyz="0 0 0"
        rpy="0 0 0" />
      <geometry>
        <mesh
          filename="package://car/meshes/front_right_axle_link.STL" />
      </geometry>
    </collision>
  </link>
  <joint
    name="front_right_axle_joint"
    type="revolute">
    <origin
      xyz="0.860739320383848 -1.01091924506277 0.47756660413794"
      rpy="1.5707963267949 0 -1.5707963267949" />
    <parent
      link="base_link" />
    <child
      link="front_right_axle_link" />
    <axis
      xyz="0 1 0" />
    <limit
      lower="-0.61"
      upper="0.61"
      effort="100"
      velocity="100" />
  </joint>
  <link
    name="front_right_wheel_link">
    <inertial>
      <origin
        xyz="0 1.11022302462516E-16 0.0250000000000004"
        rpy="0 0 0" />
      <mass
        value="6.21012679962811" />
      <inertia
        ixx="0.0721461700805678"
        ixy="-8.67361737988404E-18"
        ixz="-2.75436773507226E-18"
        iyy="0.0721461700805677"
        iyz="-5.88430285502726E-18"
        izz="0.141888005291817" />
    </inertial>
    <visual>
      <origin
        xyz="0 0 0"
        rpy="0 0 0" />
      <geometry>
        <mesh
          filename="package://car/meshes/front_right_wheel_link.STL" />
      </geometry>
      <material
        name="">
        <color
          rgba="0.792156862745098 0.819607843137255 0.933333333333333 1" />
      </material>
    </visual>
    <collision>
      <origin
        xyz="0 0 0"
        rpy="0 0 0" />
      <geometry>
        <mesh
          filename="package://car/meshes/front_right_wheel_link.STL" />
      </geometry>
    </collision>
  </link>
  <joint
    name="front_right_wheel_joint"
    type="continuous">
    <origin
      xyz="0.1 0.0249999999999999 0"
      rpy="1.5707963267949 -0.481305016641314 1.5707963267949" />
    <parent
      link="front_right_axle_link" />
    <child
      link="front_right_wheel_link" />
    <axis
      xyz="0 0 1" />
    <limit
      effort="100"
      velocity="100" />
  </joint>
  <link
    name="rear_left_axle_link">
    <inertial>
      <origin
        xyz="0.0605635681645036 0.0250000379534825 1.01927197029839E-08"
        rpy="0 0 0" />
      <mass
        value="0.225126111623143" />
      <inertia
        ixx="6.99511377566153E-05"
        ixy="-1.93887515637222E-10"
        ixz="-2.52153772939904E-10"
        iyy="0.000642301895072359"
        iyz="-2.11387437542156E-10"
        izz="0.00063284201893961" />
    </inertial>
    <visual>
      <origin
        xyz="0 0 0"
        rpy="0 0 0" />
      <geometry>
        <mesh
          filename="package://car/meshes/rear_left_axle_link.STL" />
      </geometry>
      <material
        name="">
        <color
          rgba="0.792156862745098 0.819607843137255 0.933333333333333 1" />
      </material>
    </visual>
    <collision>
      <origin
        xyz="0 0 0"
        rpy="0 0 0" />
      <geometry>
        <mesh
          filename="package://car/meshes/rear_left_axle_link.STL" />
      </geometry>
    </collision>
  </link>
  <joint
    name="rear_left_axle_joint"
    type="fixed">
    <origin
      xyz="-0.039260679616152 -0.510919245062769 0.47756660413794"
      rpy="1.5707963267949 0 1.5707963267949" />
    <parent
      link="base_link" />
    <child
      link="rear_left_axle_link" />
    <axis
      xyz="0 0 0" />
  </joint>
  <link
    name="rear_left_wheel_link">
    <inertial>
      <origin
        xyz="5.55111512312578E-17 -1.11022302462516E-16 -0.0250000000000001"
        rpy="0 0 0" />
      <mass
        value="6.2101267996281" />
      <inertia
        ixx="0.0721461700805676"
        ixy="-5.20417042793042E-18"
        ixz="-4.22428913000519E-19"
        iyy="0.0721461700805676"
        iyz="-2.23213394995521E-19"
        izz="0.141888005291817" />
    </inertial>
    <visual>
      <origin
        xyz="0 0 0"
        rpy="0 0 0" />
      <geometry>
        <mesh
          filename="package://car/meshes/rear_left_wheel_link.STL" />
      </geometry>
      <material
        name="">
        <color
          rgba="0.792156862745098 0.819607843137255 0.933333333333333 1" />
      </material>
    </visual>
    <collision>
      <origin
        xyz="0 0 0"
        rpy="0 0 0" />
      <geometry>
        <mesh
          filename="package://car/meshes/rear_left_wheel_link.STL" />
      </geometry>
    </collision>
  </link>
  <joint
    name="rear_left_wheel_joint"
    type="continuous">
    <origin
      xyz="0.0999999999999999 0.025 0"
      rpy="1.5707963267949 -1.07637270831233 -1.5707963267949" />
    <parent
      link="rear_left_axle_link" />
    <child
      link="rear_left_wheel_link" />
    <axis
      xyz="0 0 1" />
    <limit
      effort="100"
      velocity="100" />
  </joint>
  <link
    name="rear_right_axle_link">
    <inertial>
      <origin
        xyz="0.0605635681645034 -0.0250000379534825 -1.01927196891061E-08"
        rpy="0 0 0" />
      <mass
        value="0.225126111623142" />
      <inertia
        ixx="6.99511377566151E-05"
        ixy="1.93887515768374E-10"
        ixz="2.52153772834354E-10"
        iyy="0.000642301895072358"
        iyz="-2.11387437498605E-10"
        izz="0.000632842018939609" />
    </inertial>
    <visual>
      <origin
        xyz="0 0 0"
        rpy="0 0 0" />
      <geometry>
        <mesh
          filename="package://car/meshes/rear_right_axle_link.STL" />
      </geometry>
      <material
        name="">
        <color
          rgba="0.792156862745098 0.819607843137255 0.933333333333333 1" />
      </material>
    </visual>
    <collision>
      <origin
        xyz="0 0 0"
        rpy="0 0 0" />
      <geometry>
        <mesh
          filename="package://car/meshes/rear_right_axle_link.STL" />
      </geometry>
    </collision>
  </link>
  <joint
    name="rear_right_axle_joint"
    type="fixed">
    <origin
      xyz="-0.039260679616152 -1.01091924506277 0.47756660413794"
      rpy="-1.5707963267949 0 -1.5707963267949" />
    <parent
      link="base_link" />
    <child
      link="rear_right_axle_link" />
    <axis
      xyz="0 0 0" />
  </joint>
  <link
    name="rear_right_wheel_link">
    <inertial>
      <origin
        xyz="0 -1.11022302462516E-16 0.0250000000000001"
        rpy="0 0 0" />
      <mass
        value="6.21012679962811" />
      <inertia
        ixx="0.0721461700805678"
        ixy="-6.93889390390723E-18"
        ixz="-9.60477009199774E-18"
        iyy="0.0721461700805677"
        iyz="2.22704532439284E-18"
        izz="0.141888005291817" />
    </inertial>
    <visual>
      <origin
        xyz="0 0 0"
        rpy="0 0 0" />
      <geometry>
        <mesh
          filename="package://car/meshes/rear_right_wheel_link.STL" />
      </geometry>
      <material
        name="">
        <color
          rgba="0.792156862745098 0.819607843137255 0.933333333333333 1" />
      </material>
    </visual>
    <collision>
      <origin
        xyz="0 0 0"
        rpy="0 0 0" />
      <geometry>
        <mesh
          filename="package://car/meshes/rear_right_wheel_link.STL" />
      </geometry>
    </collision>
  </link>
  <joint
    name="rear_right_wheel_joint"
    type="continuous">
    <origin
      xyz="0.1 -0.0249999999999998 0"
      rpy="1.5707963267949 1.26619863601371 1.5707963267949" />
    <parent
      link="rear_right_axle_link" />
    <child
      link="rear_right_wheel_link" />
    <axis
      xyz="0 0 1" />
    <limit
      effort="100"
      velocity="100" />
  </joint>
  <link
    name="base_rotation_link">
    <inertial>
      <origin
        xyz="5.55111512312578E-17 0.0146749669182017 0.00264648868252582"
        rpy="0 0 0" />
      <mass
        value="0.46370295796515" />
      <inertia
        ixx="0.000995467414155941"
        ixy="-6.08459656610014E-21"
        ixz="-3.1527175225805E-22"
        iyy="0.00168706316869356"
        iyz="-2.4942568208495E-05"
        izz="0.000933201381575472" />
    </inertial>
    <visual>
      <origin
        xyz="0 0 0"
        rpy="0 0 0" />
      <geometry>
        <mesh
          filename="package://car/meshes/base_rotation_link.STL" />
      </geometry>
      <material
        name="">
        <color
          rgba="0.792156862745098 0.819607843137255 0.933333333333333 1" />
      </material>
    </visual>
    <collision>
      <origin
        xyz="0 0 0"
        rpy="0 0 0" />
      <geometry>
        <mesh
          filename="package://car/meshes/base_rotation_link.STL" />
      </geometry>
    </collision>
  </link>
  <joint
    name="base_rotation_joint"
    type="revolute">
    <origin
      xyz="0.410739320383848 -0.760919245062769 0.56256660413794"
      rpy="1.5707963267949 0 0" />
    <parent
      link="base_link" />
    <child
      link="base_rotation_link" />
    <axis
      xyz="0 1 0" />
    <limit
      lower="-3.14"
      upper="3.14"
      effort="100"
      velocity="100" />
  </joint>
  <link
    name="leg1_2_link">
    <inertial>
      <origin
        xyz="0.209282308677025 5.55111512312578E-17 -0.0488397578259873"
        rpy="0 0 0" />
      <mass
        value="1.05769696861129" />
      <inertia
        ixx="0.000471758035513895"
        ixy="-2.95824770501824E-18"
        ixz="-0.000234045819519474"
        iyy="0.0171278880451076"
        iyz="-2.87058378137343E-19"
        izz="0.0170643960635634" />
    </inertial>
    <visual>
      <origin
        xyz="0 0 0"
        rpy="0 0 0" />
      <geometry>
        <mesh
          filename="package://car/meshes/leg1_2_link.STL" />
      </geometry>
      <material
        name="">
        <color
          rgba="0.792156862745098 0.819607843137255 0.933333333333333 1" />
      </material>
    </visual>
    <collision>
      <origin
        xyz="0 0 0"
        rpy="0 0 0" />
      <geometry>
        <mesh
          filename="package://car/meshes/leg1_2_link.STL" />
      </geometry>
    </collision>
  </link>
  <joint
    name="leg1_2_joint"
    type="revolute">
    <origin
      xyz="0 0.0350000000000001 0"
      rpy="3.14159265358979 0 1.5707963267949" />
    <parent
      link="base_rotation_link" />
    <child
      link="leg1_2_link" />
    <axis
      xyz="0 0 1" />
    <limit
      lower="-3.14"
      upper="3.14"
      effort="100"
      velocity="100" />
  </joint>
  <link
    name="leg2_3_link">
    <inertial>
      <origin
        xyz="0.209282308677025 -1.11022302462516E-16 0.00116024217401323"
        rpy="0 0 0" />
      <mass
        value="1.0576969686113" />
      <inertia
        ixx="0.000471758035513895"
        ixy="4.42517122837199E-18"
        ixz="-0.000234045819519477"
        iyy="0.0171278880451077"
        iyz="-3.02590594772103E-21"
        izz="0.0170643960635635" />
    </inertial>
    <visual>
      <origin
        xyz="0 0 0"
        rpy="0 0 0" />
      <geometry>
        <mesh
          filename="package://car/meshes/leg2_3_link.STL" />
      </geometry>
      <material
        name="">
        <color
          rgba="0.792156862745098 0.819607843137255 0.933333333333333 1" />
      </material>
    </visual>
    <collision>
      <origin
        xyz="0 0 0"
        rpy="0 0 0" />
      <geometry>
        <mesh
          filename="package://car/meshes/leg2_3_link.STL" />
      </geometry>
    </collision>
  </link>
  <joint
    name="leg2_3_joint"
    type="revolute">
    <origin
      xyz="0.399999999999999 0 0"
      rpy="3.14159265358979 0 0" />
    <parent
      link="leg1_2_link" />
    <child
      link="leg2_3_link" />
    <axis
      xyz="0 0 1" />
    <limit
      lower="-3.14"
      upper="3.14"
      effort="100"
      velocity="100" />
  </joint>
  <link
    name="leg3_4_link">
    <inertial>
      <origin
        xyz="0.209282308677025 5.55111512312578E-17 -0.0488397578259873"
        rpy="0 0 0" />
      <mass
        value="1.0576969686113" />
      <inertia
        ixx="0.000471758035513896"
        ixy="-3.2984972653583E-18"
        ixz="-0.000234045819519485"
        iyy="0.0171278880451077"
        iyz="2.34188666232241E-20"
        izz="0.0170643960635635" />
    </inertial>
    <visual>
      <origin
        xyz="0 0 0"
        rpy="0 0 0" />
      <geometry>
        <mesh
          filename="package://car/meshes/leg3_4_link.STL" />
      </geometry>
      <material
        name="">
        <color
          rgba="0.792156862745098 0.819607843137255 0.933333333333333 1" />
      </material>
    </visual>
    <collision>
      <origin
        xyz="0 0 0"
        rpy="0 0 0" />
      <geometry>
        <mesh
          filename="package://car/meshes/leg3_4_link.STL" />
      </geometry>
    </collision>
  </link>
  <joint
    name="leg3_4_joint"
    type="revolute">
    <origin
      xyz="0.399999999999999 0 0"
      rpy="3.14159265358979 0 0" />
    <parent
      link="leg2_3_link" />
    <child
      link="leg3_4_link" />
    <axis
      xyz="0 0 1" />
    <limit
      lower="-3.14"
      upper="3.14"
      effort="100"
      velocity="100" />
  </joint>
  <link
    name="end_effector_link">
    <inertial>
      <origin
        xyz="-1.3894564165895E-08 1.70440034308328E-08 -0.0059484514282595"
        rpy="0 0 0" />
      <mass
        value="0.087095638195956" />
      <inertia
        ixx="5.36301539858517E-05"
        ixy="-7.68677606846246E-11"
        ixz="-3.80065992602011E-11"
        iyy="5.01858736172661E-05"
        iyz="2.48701289287865E-11"
        izz="4.10874831458465E-05" />
    </inertial>
    <visual>
      <origin
        xyz="0 0 0"
        rpy="0 0 0" />
      <geometry>
        <mesh
          filename="package://car/meshes/end_effector_link.STL" />
      </geometry>
      <material
        name="">
        <color
          rgba="0.792156862745098 0.819607843137255 0.933333333333333 1" />
      </material>
    </visual>
    <collision>
      <origin
        xyz="0 0 0"
        rpy="0 0 0" />
      <geometry>
        <mesh
          filename="package://car/meshes/end_effector_link.STL" />
      </geometry>
    </collision>
  </link>
  <joint
    name="end_effector_joint"
    type="revolute">
    <origin
      xyz="0.4 0 0"
      rpy="3.1416 -1.5708 0" />
    <parent
      link="leg3_4_link" />
    <child
      link="end_effector_link" />
    <axis
      xyz="1 0 0" />
    <limit
      lower="-3.14"
      upper="3.14"
      effort="100"
      velocity="100" />
  </joint>
  <link
    name="claw_top_link">
    <inertial>
      <origin
        xyz="-0.0396232269062649 0.000702572899426102 4.44089209850063E-16"
        rpy="0 0 0" />
      <mass
        value="0.0354526854795692" />
      <inertia
        ixx="3.21099761085776E-06"
        ixy="-4.82379990601232E-07"
        ixz="-1.44129514091217E-22"
        iyy="3.98194150178254E-05"
        iyz="-1.30793872042702E-22"
        izz="3.77125098067478E-05" />
    </inertial>
    <visual>
      <origin
        xyz="0 0 0"
        rpy="0 0 0" />
      <geometry>
        <mesh
          filename="package://car/meshes/claw_top_link.STL" />
      </geometry>
      <material
        name="">
        <color
          rgba="0.792156862745098 0.819607843137255 0.933333333333333 1" />
      </material>
    </visual>
    <collision>
      <origin
        xyz="0 0 0"
        rpy="0 0 0" />
      <geometry>
        <mesh
          filename="package://car/meshes/claw_top_link.STL" />
      </geometry>
    </collision>
  </link>
  <joint
    name="claw_top_joint"
    type="revolute">
    <origin
      xyz="0 0.02 -0.045"
      rpy="-1.5708 -1.4538 1.5708" />
    <parent
      link="end_effector_link" />
    <child
      link="claw_top_link" />
    <axis
      xyz="0 0 1" />
    <limit
      lower="-1.57"
      upper="0"
      effort="100"
      velocity="100" />
  </joint>
  <link
    name="claw_bottom_link">
    <inertial>
      <origin
        xyz="-0.0396232269062644 0.000702572899425769 -4.44089209850063E-16"
        rpy="0 0 0" />
      <mass
        value="0.0354526854795692" />
      <inertia
        ixx="3.21099761085776E-06"
        ixy="-4.82379990601536E-07"
        ixz="1.04292629673908E-20"
        iyy="3.98194150178253E-05"
        iyz="-6.09356122582118E-22"
        izz="3.77125098067477E-05" />
    </inertial>
    <visual>
      <origin
        xyz="0 0 0"
        rpy="0 0 0" />
      <geometry>
        <mesh
          filename="package://car/meshes/claw_bottom_link.STL" />
      </geometry>
      <material
        name="">
        <color
          rgba="0.792156862745098 0.819607843137255 0.933333333333333 1" />
      </material>
    </visual>
    <collision>
      <origin
        xyz="0 0 0"
        rpy="0 0 0" />
      <geometry>
        <mesh
          filename="package://car/meshes/claw_bottom_link.STL" />
      </geometry>
    </collision>
  </link>
  <joint
    name="claw_bottom_joint"
    type="revolute">
    <origin
      xyz="0 -0.02 -0.045"
      rpy="-1.5708 -1.499 -1.5708" />
    <parent
      link="end_effector_link" />
    <child
      link="claw_bottom_link" />
    <axis
      xyz="0 0 1" />
    <limit
      lower="-1.57"
      upper="0"
      effort="100"
      velocity="100" />
  </joint>

 <ros2_control name="GazeboSystem" type="system">
 <hardware>
     <plugin>gazebo_ros2_control/GazeboSystem</plugin>
 </hardware>

# Velocity Controllers

 <joint name="rear_left_wheel_joint">
     <command_interface name="velocity">
         <param name="min">-1000.0</param>
         <param name="max">1000.0</param>
     </command_interface>
     <state_interface name="position"/>
     <state_interface name="velocity"/>
     <!-- <state_interface name="position"/>   -->
 </joint>
 <joint name="rear_right_wheel_joint">
     <command_interface name="velocity">
         <param name="min">-1000.0</param>
         <param name="max">1000.0</param>
     </command_interface>
     <state_interface name="position"/>
     <state_interface name="velocity"/>
     <!-- <state_interface name="position"/>   -->
 </joint>
 <joint name="front_left_wheel_joint">
     <command_interface name="velocity">
         <param name="min">-1000.0</param>
         <param name="max">1000.0</param>
     </command_interface>
     <state_interface name="position"/>
     <state_interface name="velocity"/>
     <!-- <state_interface name="position"/>   -->
 </joint>
 <joint name="front_right_wheel_joint">
     <command_interface name="velocity">
         <param name="min">-1000.0</param>
         <param name="max">1000.0</param>
     </command_interface>
     <state_interface name="position"/>
     <state_interface name="velocity"/>
     <!-- <state_interface name="position"/>   -->
 </joint>
 <!-- block -->
 <!-- <joint name="front_left_axle_joint">
     <command_interface name="velocity">
         <param name="min">-3.14</param>
         <param name="max">3.14</param>
     </command_interface>
     <state_interface name="position"/>
     <state_interface name="velocity"/>
 </joint>
 <joint name="front_right_axle_joint">
     <command_interface name="velocity">
         <param name="min">-3.14</param>
         <param name="max">3.14</param>
     </command_interface>
     <state_interface name="position"/>
     <state_interface name="velocity"/>
 </joint>
 <joint name="base_rotation_joint">
     <command_interface name="velocity">
         <param name="min">-3.14</param>
         <param name="max">3.14</param>
     </command_interface>
     <state_interface name="position"/>
     <state_interface name="velocity"/>
 </joint>
 <joint name="leg1_2_joint">
     <command_interface name="velocity">
         <param name="min">-3.14</param>
         <param name="max">3.14</param>
     </command_interface>
     <state_interface name="position"/>
     <state_interface name="velocity"/>
 </joint>
 <joint name="leg2_3_joint">
     <command_interface name="velocity">
         <param name="min">-3.14</param>
         <param name="max">3.14</param>
     </command_interface>
     <state_interface name="position"/>
     <state_interface name="velocity"/>
 </joint>
 <joint name="leg3_4_joint">
     <command_interface name="velocity">
         <param name="min">-3.14</param>
         <param name="max">3.14</param>
     </command_interface>
     <state_interface name="position"/>
     <state_interface name="velocity"/>
 </joint>
 <joint name="end_effector_joint">
     <command_interface name="velocity">
         <param name="min">-3.14</param>
         <param name="max">3.14</param>
     </command_interface>
     <state_interface name="position"/>
     <state_interface name="velocity"/>
 </joint>
 <joint name="claw_top_joint">
     <command_interface name="velocity">
         <param name="min">-3.14</param>
         <param name="max">3.14</param>
     </command_interface>
     <state_interface name="position"/>
     <state_interface name="velocity"/>
 </joint>
 <joint name="claw_bottom_joint">
     <command_interface name="velocity">
         <param name="min">-3.14</param>
         <param name="max">3.14</param>
     </command_interface>
     <state_interface name="position"/>
     <state_interface name="velocity"/>
 </joint> -->
 <!-- block -->

# Position Controller
 <joint name="front_left_axle_joint">
     <command_interface name="position">
         <param name="min">-3.14</param>
         <param name="max">3.14</param>
     </command_interface>
     <state_interface name="position"/>
     <state_interface name="velocity"/>
     <!-- <state_interface name="position"/>   -->
 </joint>
 <joint name="front_right_axle_joint">
     <command_interface name="position">
         <param name="min">-3.14</param>
         <param name="max">3.14</param>
     </command_interface>
     <state_interface name="position"/>
     <state_interface name="velocity"/>
     <!-- <state_interface name="position"/>   -->
 </joint>

<!-- Block for position stuff -->
# Maniplator Controller
 <joint name="base_rotation_joint">
     <command_interface name="position">
         <param name="min">-6.28</param>
         <param name="max">6.28</param>
     </command_interface>
     <state_interface name="position"/>
     <state_interface name="velocity"/>
     <!-- <state_interface name="position"/>      -->
 </joint>
 <joint name="leg1_2_joint">
     <command_interface name="position">
         <param name="min">-6.28</param>
         <param name="max">6.28</param>
     </command_interface>
     <state_interface name="position"/>
     <state_interface name="velocity"/>
     <!-- <state_interface name="position"/>      -->
 </joint>
 <joint name="leg2_3_joint">
     <command_interface name="position">
         <param name="min">-6.28</param>
         <param name="max">6.28</param>
     </command_interface>
     <state_interface name="position"/>
     <state_interface name="velocity"/>
     <!-- <state_interface name="position"/>      -->
 </joint>
 <joint name="leg3_4_joint">
     <command_interface name="position">
         <param name="min">-6.28</param>
         <param name="max">6.28</param>
     </command_interface>
     <state_interface name="position"/>
     <state_interface name="velocity"/>
     <!-- <state_interface name="position"/>      -->
 </joint>
 <joint name="end_effector_joint">
     <command_interface name="position">
         <param name="min">-6.28</param>
         <param name="max">6.28</param>
     </command_interface>
     <state_interface name="position"/>
     <state_interface name="velocity"/>
     <!-- <state_interface name="position"/>      -->
 </joint>
 <joint name="claw_top_joint">
     <command_interface name="position">
         <param name="min">-6.28</param>
         <param name="max">6.28</param>
     </command_interface>
     <state_interface name="position"/>
     <state_interface name="velocity"/>
     <!-- <state_interface name="position"/>      -->
 </joint>
 <joint name="claw_bottom_joint">
     <command_interface name="position">
         <param name="min">-6.28</param>
         <param name="max">6.28</param>
     </command_interface>
     <state_interface name="position"/>
     <state_interface name="velocity"/>
     <!-- <state_interface name="position"/>       -->
 </joint>
<!-- /Block for position stuff -->
 
 </ros2_control>
 <gazebo>
    <plugin filename="libgazebo_ros2_control.so" name="gazebo_ros2_control">
        <parameters>$(find car)/config/control.yaml</parameters>
    </plugin>
</gazebo>
</robot>